2025-05-01 20:58:07,818 [WARNING] django.request: Not Found: /favicon.ico
2025-05-01 20:58:43,924 [WARNING] django.request: Not Found: /dashboard/dist/img/default-150x150.png
2025-05-01 20:58:43,990 [WARNING] django.request: Not Found: /dashboard/dist/img/default-150x150.png
2025-05-01 20:58:44,553 [ERROR] django.request: Internal Server Error: /products/productsList
Traceback (most recent call last):
  File "C:\Users\HP\video-streaming-project\stream\myenv\Lib\site-packages\requests\models.py", line 974, in json
    return complexjson.loads(self.text, **kwargs)
           ^^^^^^^^^^^^^^^^^^^^^^^^^^^^^^^^^^^^^^
  File "C:\Program Files\WindowsApps\PythonSoftwareFoundation.Python.3.12_3.12.2800.0_x64__qbz5n2kfra8p0\Lib\json\__init__.py", line 346, in loads
    return _default_decoder.decode(s)
           ^^^^^^^^^^^^^^^^^^^^^^^^^^
  File "C:\Program Files\WindowsApps\PythonSoftwareFoundation.Python.3.12_3.12.2800.0_x64__qbz5n2kfra8p0\Lib\json\decoder.py", line 338, in decode
    obj, end = self.raw_decode(s, idx=_w(s, 0).end())
               ^^^^^^^^^^^^^^^^^^^^^^^^^^^^^^^^^^^^^^
  File "C:\Program Files\WindowsApps\PythonSoftwareFoundation.Python.3.12_3.12.2800.0_x64__qbz5n2kfra8p0\Lib\json\decoder.py", line 356, in raw_decode
    raise JSONDecodeError("Expecting value", s, err.value) from None
json.decoder.JSONDecodeError: Expecting value: line 1 column 1 (char 0)

During handling of the above exception, another exception occurred:

Traceback (most recent call last):
  File "C:\Users\HP\video-streaming-project\stream\myenv\Lib\site-packages\django\core\handlers\exception.py", line 55, in inner
    response = get_response(request)
               ^^^^^^^^^^^^^^^^^^^^^
  File "C:\Users\HP\video-streaming-project\stream\myenv\Lib\site-packages\django\core\handlers\base.py", line 197, in _get_response
    response = wrapped_callback(request, *callback_args, **callback_kwargs)
               ^^^^^^^^^^^^^^^^^^^^^^^^^^^^^^^^^^^^^^^^^^^^^^^^^^^^^^^^^^^^
  File "C:\Users\HP\video-streaming-project\stream\myenv\Lib\site-packages\django\views\generic\base.py", line 104, in view
    return self.dispatch(request, *args, **kwargs)
           ^^^^^^^^^^^^^^^^^^^^^^^^^^^^^^^^^^^^^^^
  File "C:\Users\HP\video-streaming-project\stream\myenv\Lib\site-packages\django\views\generic\base.py", line 143, in dispatch
    return handler(request, *args, **kwargs)
           ^^^^^^^^^^^^^^^^^^^^^^^^^^^^^^^^^
  File "C:\Users\HP\ManishERP\ecommerce-ui\base\products\views.py", line 25, in get
    data = response.json()
           ^^^^^^^^^^^^^^^
  File "C:\Users\HP\video-streaming-project\stream\myenv\Lib\site-packages\requests\models.py", line 978, in json
    raise RequestsJSONDecodeError(e.msg, e.doc, e.pos)
requests.exceptions.JSONDecodeError: Expecting value: line 1 column 1 (char 0)
2025-05-01 20:58:45,822 [WARNING] django.request: Not Found: /user/logout/
2025-05-01 21:01:26,407 [WARNING] django.request: Not Found: /user/logout/
2025-05-01 21:01:35,637 [WARNING] django.request: Not Found: /favicon.ico
2025-05-01 21:07:08,141 [WARNING] django.request: Not Found: /user/logout/
2025-05-01 21:07:10,612 [WARNING] django.request: Not Found: /favicon.ico
2025-05-01 21:08:35,908 [WARNING] django.request: Not Found: /user/logout/
2025-05-01 21:08:36,408 [WARNING] django.request: Not Found: /favicon.ico
2025-05-01 21:09:17,153 [WARNING] django.request: Not Found: /user/logout/
2025-05-01 21:09:17,657 [WARNING] django.request: Not Found: /favicon.ico
2025-05-01 21:09:58,334 [WARNING] django.request: Not Found: /user/logout/
2025-05-01 21:09:59,178 [WARNING] django.request: Not Found: /favicon.ico
2025-05-01 21:23:51,990 [ERROR] django.request: Internal Server Error: /master/generalSettings/create
Traceback (most recent call last):
  File "C:\Users\HP\video-streaming-project\stream\myenv\Lib\site-packages\urllib3\connection.py", line 198, in _new_conn
    sock = connection.create_connection(
           ^^^^^^^^^^^^^^^^^^^^^^^^^^^^^
  File "C:\Users\HP\video-streaming-project\stream\myenv\Lib\site-packages\urllib3\util\connection.py", line 85, in create_connection
    raise err
  File "C:\Users\HP\video-streaming-project\stream\myenv\Lib\site-packages\urllib3\util\connection.py", line 73, in create_connection
    sock.connect(sa)
ConnectionRefusedError: [WinError 10061] No connection could be made because the target machine actively refused it

The above exception was the direct cause of the following exception:

Traceback (most recent call last):
  File "C:\Users\HP\video-streaming-project\stream\myenv\Lib\site-packages\urllib3\connectionpool.py", line 787, in urlopen
    response = self._make_request(
               ^^^^^^^^^^^^^^^^^^^
  File "C:\Users\HP\video-streaming-project\stream\myenv\Lib\site-packages\urllib3\connectionpool.py", line 493, in _make_request
    conn.request(
  File "C:\Users\HP\video-streaming-project\stream\myenv\Lib\site-packages\urllib3\connection.py", line 445, in request
    self.endheaders()
  File "C:\Program Files\WindowsApps\PythonSoftwareFoundation.Python.3.12_3.12.2800.0_x64__qbz5n2kfra8p0\Lib\http\client.py", line 1333, in endheaders
    self._send_output(message_body, encode_chunked=encode_chunked)
  File "C:\Program Files\WindowsApps\PythonSoftwareFoundation.Python.3.12_3.12.2800.0_x64__qbz5n2kfra8p0\Lib\http\client.py", line 1093, in _send_output
    self.send(msg)
  File "C:\Program Files\WindowsApps\PythonSoftwareFoundation.Python.3.12_3.12.2800.0_x64__qbz5n2kfra8p0\Lib\http\client.py", line 1037, in send
    self.connect()
  File "C:\Users\HP\video-streaming-project\stream\myenv\Lib\site-packages\urllib3\connection.py", line 276, in connect
    self.sock = self._new_conn()
                ^^^^^^^^^^^^^^^^
  File "C:\Users\HP\video-streaming-project\stream\myenv\Lib\site-packages\urllib3\connection.py", line 213, in _new_conn
    raise NewConnectionError(
urllib3.exceptions.NewConnectionError: <urllib3.connection.HTTPConnection object at 0x00000296AED900B0>: Failed to establish a new connection: [WinError 10061] No connection could be made because the target machine actively refused it

The above exception was the direct cause of the following exception:

Traceback (most recent call last):
  File "C:\Users\HP\video-streaming-project\stream\myenv\Lib\site-packages\requests\adapters.py", line 667, in send
    resp = conn.urlopen(
           ^^^^^^^^^^^^^
  File "C:\Users\HP\video-streaming-project\stream\myenv\Lib\site-packages\urllib3\connectionpool.py", line 841, in urlopen
    retries = retries.increment(
              ^^^^^^^^^^^^^^^^^^
  File "C:\Users\HP\video-streaming-project\stream\myenv\Lib\site-packages\urllib3\util\retry.py", line 519, in increment
    raise MaxRetryError(_pool, url, reason) from reason  # type: ignore[arg-type]
    ^^^^^^^^^^^^^^^^^^^^^^^^^^^^^^^^^^^^^^^^^^^^^^^^^^^
urllib3.exceptions.MaxRetryError: HTTPConnectionPool(host='127.0.0.1', port=8000): Max retries exceeded with url: /district/create (Caused by NewConnectionError('<urllib3.connection.HTTPConnection object at 0x00000296AED900B0>: Failed to establish a new connection: [WinError 10061] No connection could be made because the target machine actively refused it'))

During handling of the above exception, another exception occurred:

Traceback (most recent call last):
  File "C:\Users\HP\video-streaming-project\stream\myenv\Lib\site-packages\django\core\handlers\exception.py", line 55, in inner
    response = get_response(request)
               ^^^^^^^^^^^^^^^^^^^^^
  File "C:\Users\HP\video-streaming-project\stream\myenv\Lib\site-packages\django\core\handlers\base.py", line 197, in _get_response
    response = wrapped_callback(request, *callback_args, **callback_kwargs)
               ^^^^^^^^^^^^^^^^^^^^^^^^^^^^^^^^^^^^^^^^^^^^^^^^^^^^^^^^^^^^
  File "C:\Users\HP\video-streaming-project\stream\myenv\Lib\site-packages\django\views\generic\base.py", line 104, in view
    return self.dispatch(request, *args, **kwargs)
           ^^^^^^^^^^^^^^^^^^^^^^^^^^^^^^^^^^^^^^^
  File "C:\Users\HP\video-streaming-project\stream\myenv\Lib\site-packages\django\views\generic\base.py", line 143, in dispatch
    return handler(request, *args, **kwargs)
           ^^^^^^^^^^^^^^^^^^^^^^^^^^^^^^^^^
  File "C:\Users\HP\ManishERP\ecommerce-ui\base\master\views\views_contact_master.py", line 34, in post
    response = requests.post(api_url, json=data, headers=headers)
               ^^^^^^^^^^^^^^^^^^^^^^^^^^^^^^^^^^^^^^^^^^^^^^^^^^
  File "C:\Users\HP\video-streaming-project\stream\myenv\Lib\site-packages\requests\api.py", line 115, in post
    return request("post", url, data=data, json=json, **kwargs)
           ^^^^^^^^^^^^^^^^^^^^^^^^^^^^^^^^^^^^^^^^^^^^^^^^^^^^
  File "C:\Users\HP\video-streaming-project\stream\myenv\Lib\site-packages\requests\api.py", line 59, in request
    return session.request(method=method, url=url, **kwargs)
           ^^^^^^^^^^^^^^^^^^^^^^^^^^^^^^^^^^^^^^^^^^^^^^^^^
  File "C:\Users\HP\video-streaming-project\stream\myenv\Lib\site-packages\requests\sessions.py", line 589, in request
    resp = self.send(prep, **send_kwargs)
           ^^^^^^^^^^^^^^^^^^^^^^^^^^^^^^
  File "C:\Users\HP\video-streaming-project\stream\myenv\Lib\site-packages\requests\sessions.py", line 703, in send
    r = adapter.send(request, **kwargs)
        ^^^^^^^^^^^^^^^^^^^^^^^^^^^^^^^
  File "C:\Users\HP\video-streaming-project\stream\myenv\Lib\site-packages\requests\adapters.py", line 700, in send
    raise ConnectionError(e, request=request)
requests.exceptions.ConnectionError: HTTPConnectionPool(host='127.0.0.1', port=8000): Max retries exceeded with url: /district/create (Caused by NewConnectionError('<urllib3.connection.HTTPConnection object at 0x00000296AED900B0>: Failed to establish a new connection: [WinError 10061] No connection could be made because the target machine actively refused it'))
2025-05-01 21:27:01,370 [ERROR] django.request: Internal Server Error: /master/generalSettings/create
Traceback (most recent call last):
  File "C:\Users\HP\video-streaming-project\stream\myenv\Lib\site-packages\requests\models.py", line 974, in json
    return complexjson.loads(self.text, **kwargs)
           ^^^^^^^^^^^^^^^^^^^^^^^^^^^^^^^^^^^^^^
  File "C:\Program Files\WindowsApps\PythonSoftwareFoundation.Python.3.12_3.12.2800.0_x64__qbz5n2kfra8p0\Lib\json\__init__.py", line 346, in loads
    return _default_decoder.decode(s)
           ^^^^^^^^^^^^^^^^^^^^^^^^^^
  File "C:\Program Files\WindowsApps\PythonSoftwareFoundation.Python.3.12_3.12.2800.0_x64__qbz5n2kfra8p0\Lib\json\decoder.py", line 338, in decode
    obj, end = self.raw_decode(s, idx=_w(s, 0).end())
               ^^^^^^^^^^^^^^^^^^^^^^^^^^^^^^^^^^^^^^
  File "C:\Program Files\WindowsApps\PythonSoftwareFoundation.Python.3.12_3.12.2800.0_x64__qbz5n2kfra8p0\Lib\json\decoder.py", line 356, in raw_decode
    raise JSONDecodeError("Expecting value", s, err.value) from None
json.decoder.JSONDecodeError: Expecting value: line 1 column 1 (char 0)

During handling of the above exception, another exception occurred:

Traceback (most recent call last):
  File "C:\Users\HP\video-streaming-project\stream\myenv\Lib\site-packages\django\core\handlers\exception.py", line 55, in inner
    response = get_response(request)
               ^^^^^^^^^^^^^^^^^^^^^
  File "C:\Users\HP\video-streaming-project\stream\myenv\Lib\site-packages\django\core\handlers\base.py", line 197, in _get_response
    response = wrapped_callback(request, *callback_args, **callback_kwargs)
               ^^^^^^^^^^^^^^^^^^^^^^^^^^^^^^^^^^^^^^^^^^^^^^^^^^^^^^^^^^^^
  File "C:\Users\HP\video-streaming-project\stream\myenv\Lib\site-packages\django\views\generic\base.py", line 104, in view
    return self.dispatch(request, *args, **kwargs)
           ^^^^^^^^^^^^^^^^^^^^^^^^^^^^^^^^^^^^^^^
  File "C:\Users\HP\video-streaming-project\stream\myenv\Lib\site-packages\django\views\generic\base.py", line 143, in dispatch
    return handler(request, *args, **kwargs)
           ^^^^^^^^^^^^^^^^^^^^^^^^^^^^^^^^^
  File "C:\Users\HP\ManishERP\ecommerce-ui\base\master\views\views_contact_master.py", line 39, in post
    return JsonResponse(response.json(), status=500)
                        ^^^^^^^^^^^^^^^
  File "C:\Users\HP\video-streaming-project\stream\myenv\Lib\site-packages\requests\models.py", line 978, in json
    raise RequestsJSONDecodeError(e.msg, e.doc, e.pos)
requests.exceptions.JSONDecodeError: Expecting value: line 1 column 1 (char 0)
2025-05-01 21:28:08,085 [ERROR] django.request: Internal Server Error: /master/generalSettings/create
Traceback (most recent call last):
  File "C:\Users\HP\video-streaming-project\stream\myenv\Lib\site-packages\requests\models.py", line 974, in json
    return complexjson.loads(self.text, **kwargs)
           ^^^^^^^^^^^^^^^^^^^^^^^^^^^^^^^^^^^^^^
  File "C:\Program Files\WindowsApps\PythonSoftwareFoundation.Python.3.12_3.12.2800.0_x64__qbz5n2kfra8p0\Lib\json\__init__.py", line 346, in loads
    return _default_decoder.decode(s)
           ^^^^^^^^^^^^^^^^^^^^^^^^^^
  File "C:\Program Files\WindowsApps\PythonSoftwareFoundation.Python.3.12_3.12.2800.0_x64__qbz5n2kfra8p0\Lib\json\decoder.py", line 338, in decode
    obj, end = self.raw_decode(s, idx=_w(s, 0).end())
               ^^^^^^^^^^^^^^^^^^^^^^^^^^^^^^^^^^^^^^
  File "C:\Program Files\WindowsApps\PythonSoftwareFoundation.Python.3.12_3.12.2800.0_x64__qbz5n2kfra8p0\Lib\json\decoder.py", line 356, in raw_decode
    raise JSONDecodeError("Expecting value", s, err.value) from None
json.decoder.JSONDecodeError: Expecting value: line 1 column 1 (char 0)

During handling of the above exception, another exception occurred:

Traceback (most recent call last):
  File "C:\Users\HP\video-streaming-project\stream\myenv\Lib\site-packages\django\core\handlers\exception.py", line 55, in inner
    response = get_response(request)
               ^^^^^^^^^^^^^^^^^^^^^
  File "C:\Users\HP\video-streaming-project\stream\myenv\Lib\site-packages\django\core\handlers\base.py", line 197, in _get_response
    response = wrapped_callback(request, *callback_args, **callback_kwargs)
               ^^^^^^^^^^^^^^^^^^^^^^^^^^^^^^^^^^^^^^^^^^^^^^^^^^^^^^^^^^^^
  File "C:\Users\HP\video-streaming-project\stream\myenv\Lib\site-packages\django\views\generic\base.py", line 104, in view
    return self.dispatch(request, *args, **kwargs)
           ^^^^^^^^^^^^^^^^^^^^^^^^^^^^^^^^^^^^^^^
  File "C:\Users\HP\video-streaming-project\stream\myenv\Lib\site-packages\django\views\generic\base.py", line 143, in dispatch
    return handler(request, *args, **kwargs)
           ^^^^^^^^^^^^^^^^^^^^^^^^^^^^^^^^^
  File "C:\Users\HP\ManishERP\ecommerce-ui\base\master\views\views_contact_master.py", line 39, in post
    return JsonResponse(response.json(), status=500)
                        ^^^^^^^^^^^^^^^
  File "C:\Users\HP\video-streaming-project\stream\myenv\Lib\site-packages\requests\models.py", line 978, in json
    raise RequestsJSONDecodeError(e.msg, e.doc, e.pos)
requests.exceptions.JSONDecodeError: Expecting value: line 1 column 1 (char 0)
2025-05-01 21:31:41,097 [ERROR] django.request: Internal Server Error: /master/generalSettings/create
Traceback (most recent call last):
  File "C:\Users\HP\video-streaming-project\stream\myenv\Lib\site-packages\requests\models.py", line 974, in json
    return complexjson.loads(self.text, **kwargs)
           ^^^^^^^^^^^^^^^^^^^^^^^^^^^^^^^^^^^^^^
  File "C:\Program Files\WindowsApps\PythonSoftwareFoundation.Python.3.12_3.12.2800.0_x64__qbz5n2kfra8p0\Lib\json\__init__.py", line 346, in loads
    return _default_decoder.decode(s)
           ^^^^^^^^^^^^^^^^^^^^^^^^^^
  File "C:\Program Files\WindowsApps\PythonSoftwareFoundation.Python.3.12_3.12.2800.0_x64__qbz5n2kfra8p0\Lib\json\decoder.py", line 338, in decode
    obj, end = self.raw_decode(s, idx=_w(s, 0).end())
               ^^^^^^^^^^^^^^^^^^^^^^^^^^^^^^^^^^^^^^
  File "C:\Program Files\WindowsApps\PythonSoftwareFoundation.Python.3.12_3.12.2800.0_x64__qbz5n2kfra8p0\Lib\json\decoder.py", line 356, in raw_decode
    raise JSONDecodeError("Expecting value", s, err.value) from None
json.decoder.JSONDecodeError: Expecting value: line 1 column 1 (char 0)

During handling of the above exception, another exception occurred:

Traceback (most recent call last):
  File "C:\Users\HP\video-streaming-project\stream\myenv\Lib\site-packages\django\core\handlers\exception.py", line 55, in inner
    response = get_response(request)
               ^^^^^^^^^^^^^^^^^^^^^
  File "C:\Users\HP\video-streaming-project\stream\myenv\Lib\site-packages\django\core\handlers\base.py", line 197, in _get_response
    response = wrapped_callback(request, *callback_args, **callback_kwargs)
               ^^^^^^^^^^^^^^^^^^^^^^^^^^^^^^^^^^^^^^^^^^^^^^^^^^^^^^^^^^^^
  File "C:\Users\HP\video-streaming-project\stream\myenv\Lib\site-packages\django\views\generic\base.py", line 104, in view
    return self.dispatch(request, *args, **kwargs)
           ^^^^^^^^^^^^^^^^^^^^^^^^^^^^^^^^^^^^^^^
  File "C:\Users\HP\video-streaming-project\stream\myenv\Lib\site-packages\django\views\generic\base.py", line 143, in dispatch
    return handler(request, *args, **kwargs)
           ^^^^^^^^^^^^^^^^^^^^^^^^^^^^^^^^^
  File "C:\Users\HP\ManishERP\ecommerce-ui\base\master\views\views_contact_master.py", line 39, in post
    return JsonResponse(response.json(), status=500)
                        ^^^^^^^^^^^^^^^
  File "C:\Users\HP\video-streaming-project\stream\myenv\Lib\site-packages\requests\models.py", line 978, in json
    raise RequestsJSONDecodeError(e.msg, e.doc, e.pos)
requests.exceptions.JSONDecodeError: Expecting value: line 1 column 1 (char 0)
2025-05-01 21:31:57,783 [ERROR] django.request: Internal Server Error: /master/generalSettings/create
Traceback (most recent call last):
  File "C:\Users\HP\video-streaming-project\stream\myenv\Lib\site-packages\requests\models.py", line 974, in json
    return complexjson.loads(self.text, **kwargs)
           ^^^^^^^^^^^^^^^^^^^^^^^^^^^^^^^^^^^^^^
  File "C:\Program Files\WindowsApps\PythonSoftwareFoundation.Python.3.12_3.12.2800.0_x64__qbz5n2kfra8p0\Lib\json\__init__.py", line 346, in loads
    return _default_decoder.decode(s)
           ^^^^^^^^^^^^^^^^^^^^^^^^^^
  File "C:\Program Files\WindowsApps\PythonSoftwareFoundation.Python.3.12_3.12.2800.0_x64__qbz5n2kfra8p0\Lib\json\decoder.py", line 338, in decode
    obj, end = self.raw_decode(s, idx=_w(s, 0).end())
               ^^^^^^^^^^^^^^^^^^^^^^^^^^^^^^^^^^^^^^
  File "C:\Program Files\WindowsApps\PythonSoftwareFoundation.Python.3.12_3.12.2800.0_x64__qbz5n2kfra8p0\Lib\json\decoder.py", line 356, in raw_decode
    raise JSONDecodeError("Expecting value", s, err.value) from None
json.decoder.JSONDecodeError: Expecting value: line 1 column 1 (char 0)

During handling of the above exception, another exception occurred:

Traceback (most recent call last):
  File "C:\Users\HP\video-streaming-project\stream\myenv\Lib\site-packages\django\core\handlers\exception.py", line 55, in inner
    response = get_response(request)
               ^^^^^^^^^^^^^^^^^^^^^
  File "C:\Users\HP\video-streaming-project\stream\myenv\Lib\site-packages\django\core\handlers\base.py", line 197, in _get_response
    response = wrapped_callback(request, *callback_args, **callback_kwargs)
               ^^^^^^^^^^^^^^^^^^^^^^^^^^^^^^^^^^^^^^^^^^^^^^^^^^^^^^^^^^^^
  File "C:\Users\HP\video-streaming-project\stream\myenv\Lib\site-packages\django\views\generic\base.py", line 104, in view
    return self.dispatch(request, *args, **kwargs)
           ^^^^^^^^^^^^^^^^^^^^^^^^^^^^^^^^^^^^^^^
  File "C:\Users\HP\video-streaming-project\stream\myenv\Lib\site-packages\django\views\generic\base.py", line 143, in dispatch
    return handler(request, *args, **kwargs)
           ^^^^^^^^^^^^^^^^^^^^^^^^^^^^^^^^^
  File "C:\Users\HP\ManishERP\ecommerce-ui\base\master\views\views_contact_master.py", line 39, in post
    return JsonResponse(response.json(), status=500)
                        ^^^^^^^^^^^^^^^
  File "C:\Users\HP\video-streaming-project\stream\myenv\Lib\site-packages\requests\models.py", line 978, in json
    raise RequestsJSONDecodeError(e.msg, e.doc, e.pos)
requests.exceptions.JSONDecodeError: Expecting value: line 1 column 1 (char 0)
2025-05-01 21:34:51,877 [ERROR] django.request: Internal Server Error: /master/generalSettings/create
Traceback (most recent call last):
  File "C:\Users\HP\video-streaming-project\stream\myenv\Lib\site-packages\requests\models.py", line 974, in json
    return complexjson.loads(self.text, **kwargs)
           ^^^^^^^^^^^^^^^^^^^^^^^^^^^^^^^^^^^^^^
  File "C:\Program Files\WindowsApps\PythonSoftwareFoundation.Python.3.12_3.12.2800.0_x64__qbz5n2kfra8p0\Lib\json\__init__.py", line 346, in loads
    return _default_decoder.decode(s)
           ^^^^^^^^^^^^^^^^^^^^^^^^^^
  File "C:\Program Files\WindowsApps\PythonSoftwareFoundation.Python.3.12_3.12.2800.0_x64__qbz5n2kfra8p0\Lib\json\decoder.py", line 338, in decode
    obj, end = self.raw_decode(s, idx=_w(s, 0).end())
               ^^^^^^^^^^^^^^^^^^^^^^^^^^^^^^^^^^^^^^
  File "C:\Program Files\WindowsApps\PythonSoftwareFoundation.Python.3.12_3.12.2800.0_x64__qbz5n2kfra8p0\Lib\json\decoder.py", line 356, in raw_decode
    raise JSONDecodeError("Expecting value", s, err.value) from None
json.decoder.JSONDecodeError: Expecting value: line 1 column 1 (char 0)

During handling of the above exception, another exception occurred:

Traceback (most recent call last):
  File "C:\Users\HP\video-streaming-project\stream\myenv\Lib\site-packages\django\core\handlers\exception.py", line 55, in inner
    response = get_response(request)
               ^^^^^^^^^^^^^^^^^^^^^
  File "C:\Users\HP\video-streaming-project\stream\myenv\Lib\site-packages\django\core\handlers\base.py", line 197, in _get_response
    response = wrapped_callback(request, *callback_args, **callback_kwargs)
               ^^^^^^^^^^^^^^^^^^^^^^^^^^^^^^^^^^^^^^^^^^^^^^^^^^^^^^^^^^^^
  File "C:\Users\HP\video-streaming-project\stream\myenv\Lib\site-packages\django\views\generic\base.py", line 104, in view
    return self.dispatch(request, *args, **kwargs)
           ^^^^^^^^^^^^^^^^^^^^^^^^^^^^^^^^^^^^^^^
  File "C:\Users\HP\video-streaming-project\stream\myenv\Lib\site-packages\django\views\generic\base.py", line 143, in dispatch
    return handler(request, *args, **kwargs)
           ^^^^^^^^^^^^^^^^^^^^^^^^^^^^^^^^^
  File "C:\Users\HP\ManishERP\ecommerce-ui\base\master\views\views_contact_master.py", line 39, in post
    return JsonResponse(response.json(), status=500)
                        ^^^^^^^^^^^^^^^
  File "C:\Users\HP\video-streaming-project\stream\myenv\Lib\site-packages\requests\models.py", line 978, in json
    raise RequestsJSONDecodeError(e.msg, e.doc, e.pos)
requests.exceptions.JSONDecodeError: Expecting value: line 1 column 1 (char 0)
2025-05-01 21:35:39,379 [ERROR] django.request: Internal Server Error: /master/generalSettings/create
Traceback (most recent call last):
  File "C:\Users\HP\video-streaming-project\stream\myenv\Lib\site-packages\requests\models.py", line 974, in json
    return complexjson.loads(self.text, **kwargs)
           ^^^^^^^^^^^^^^^^^^^^^^^^^^^^^^^^^^^^^^
  File "C:\Program Files\WindowsApps\PythonSoftwareFoundation.Python.3.12_3.12.2800.0_x64__qbz5n2kfra8p0\Lib\json\__init__.py", line 346, in loads
    return _default_decoder.decode(s)
           ^^^^^^^^^^^^^^^^^^^^^^^^^^
  File "C:\Program Files\WindowsApps\PythonSoftwareFoundation.Python.3.12_3.12.2800.0_x64__qbz5n2kfra8p0\Lib\json\decoder.py", line 338, in decode
    obj, end = self.raw_decode(s, idx=_w(s, 0).end())
               ^^^^^^^^^^^^^^^^^^^^^^^^^^^^^^^^^^^^^^
  File "C:\Program Files\WindowsApps\PythonSoftwareFoundation.Python.3.12_3.12.2800.0_x64__qbz5n2kfra8p0\Lib\json\decoder.py", line 356, in raw_decode
    raise JSONDecodeError("Expecting value", s, err.value) from None
json.decoder.JSONDecodeError: Expecting value: line 1 column 1 (char 0)

During handling of the above exception, another exception occurred:

Traceback (most recent call last):
  File "C:\Users\HP\video-streaming-project\stream\myenv\Lib\site-packages\django\core\handlers\exception.py", line 55, in inner
    response = get_response(request)
               ^^^^^^^^^^^^^^^^^^^^^
  File "C:\Users\HP\video-streaming-project\stream\myenv\Lib\site-packages\django\core\handlers\base.py", line 197, in _get_response
    response = wrapped_callback(request, *callback_args, **callback_kwargs)
               ^^^^^^^^^^^^^^^^^^^^^^^^^^^^^^^^^^^^^^^^^^^^^^^^^^^^^^^^^^^^
  File "C:\Users\HP\video-streaming-project\stream\myenv\Lib\site-packages\django\views\generic\base.py", line 104, in view
    return self.dispatch(request, *args, **kwargs)
           ^^^^^^^^^^^^^^^^^^^^^^^^^^^^^^^^^^^^^^^
  File "C:\Users\HP\video-streaming-project\stream\myenv\Lib\site-packages\django\views\generic\base.py", line 143, in dispatch
    return handler(request, *args, **kwargs)
           ^^^^^^^^^^^^^^^^^^^^^^^^^^^^^^^^^
  File "C:\Users\HP\ManishERP\ecommerce-ui\base\master\views\views_contact_master.py", line 39, in post
    return JsonResponse(response.json(), status=500)
                        ^^^^^^^^^^^^^^^
  File "C:\Users\HP\video-streaming-project\stream\myenv\Lib\site-packages\requests\models.py", line 978, in json
    raise RequestsJSONDecodeError(e.msg, e.doc, e.pos)
requests.exceptions.JSONDecodeError: Expecting value: line 1 column 1 (char 0)
2025-05-01 21:36:31,112 [ERROR] django.request: Internal Server Error: /master/generalSettings/create
Traceback (most recent call last):
  File "C:\Users\HP\video-streaming-project\stream\myenv\Lib\site-packages\requests\models.py", line 974, in json
    return complexjson.loads(self.text, **kwargs)
           ^^^^^^^^^^^^^^^^^^^^^^^^^^^^^^^^^^^^^^
  File "C:\Program Files\WindowsApps\PythonSoftwareFoundation.Python.3.12_3.12.2800.0_x64__qbz5n2kfra8p0\Lib\json\__init__.py", line 346, in loads
    return _default_decoder.decode(s)
           ^^^^^^^^^^^^^^^^^^^^^^^^^^
  File "C:\Program Files\WindowsApps\PythonSoftwareFoundation.Python.3.12_3.12.2800.0_x64__qbz5n2kfra8p0\Lib\json\decoder.py", line 338, in decode
    obj, end = self.raw_decode(s, idx=_w(s, 0).end())
               ^^^^^^^^^^^^^^^^^^^^^^^^^^^^^^^^^^^^^^
  File "C:\Program Files\WindowsApps\PythonSoftwareFoundation.Python.3.12_3.12.2800.0_x64__qbz5n2kfra8p0\Lib\json\decoder.py", line 356, in raw_decode
    raise JSONDecodeError("Expecting value", s, err.value) from None
json.decoder.JSONDecodeError: Expecting value: line 1 column 1 (char 0)

During handling of the above exception, another exception occurred:

Traceback (most recent call last):
  File "C:\Users\HP\video-streaming-project\stream\myenv\Lib\site-packages\django\core\handlers\exception.py", line 55, in inner
    response = get_response(request)
               ^^^^^^^^^^^^^^^^^^^^^
  File "C:\Users\HP\video-streaming-project\stream\myenv\Lib\site-packages\django\core\handlers\base.py", line 197, in _get_response
    response = wrapped_callback(request, *callback_args, **callback_kwargs)
               ^^^^^^^^^^^^^^^^^^^^^^^^^^^^^^^^^^^^^^^^^^^^^^^^^^^^^^^^^^^^
  File "C:\Users\HP\video-streaming-project\stream\myenv\Lib\site-packages\django\views\generic\base.py", line 104, in view
    return self.dispatch(request, *args, **kwargs)
           ^^^^^^^^^^^^^^^^^^^^^^^^^^^^^^^^^^^^^^^
  File "C:\Users\HP\video-streaming-project\stream\myenv\Lib\site-packages\django\views\generic\base.py", line 143, in dispatch
    return handler(request, *args, **kwargs)
           ^^^^^^^^^^^^^^^^^^^^^^^^^^^^^^^^^
  File "C:\Users\HP\ManishERP\ecommerce-ui\base\master\views\views_contact_master.py", line 39, in post
    return JsonResponse(response.json(), status=500)
                        ^^^^^^^^^^^^^^^
  File "C:\Users\HP\video-streaming-project\stream\myenv\Lib\site-packages\requests\models.py", line 978, in json
    raise RequestsJSONDecodeError(e.msg, e.doc, e.pos)
requests.exceptions.JSONDecodeError: Expecting value: line 1 column 1 (char 0)
2025-05-01 21:39:00,050 [ERROR] django.request: Internal Server Error: /master/generalSettings/create
Traceback (most recent call last):
  File "C:\Users\HP\video-streaming-project\stream\myenv\Lib\site-packages\requests\models.py", line 974, in json
    return complexjson.loads(self.text, **kwargs)
           ^^^^^^^^^^^^^^^^^^^^^^^^^^^^^^^^^^^^^^
  File "C:\Program Files\WindowsApps\PythonSoftwareFoundation.Python.3.12_3.12.2800.0_x64__qbz5n2kfra8p0\Lib\json\__init__.py", line 346, in loads
    return _default_decoder.decode(s)
           ^^^^^^^^^^^^^^^^^^^^^^^^^^
  File "C:\Program Files\WindowsApps\PythonSoftwareFoundation.Python.3.12_3.12.2800.0_x64__qbz5n2kfra8p0\Lib\json\decoder.py", line 338, in decode
    obj, end = self.raw_decode(s, idx=_w(s, 0).end())
               ^^^^^^^^^^^^^^^^^^^^^^^^^^^^^^^^^^^^^^
  File "C:\Program Files\WindowsApps\PythonSoftwareFoundation.Python.3.12_3.12.2800.0_x64__qbz5n2kfra8p0\Lib\json\decoder.py", line 356, in raw_decode
    raise JSONDecodeError("Expecting value", s, err.value) from None
json.decoder.JSONDecodeError: Expecting value: line 1 column 1 (char 0)

During handling of the above exception, another exception occurred:

Traceback (most recent call last):
  File "C:\Users\HP\video-streaming-project\stream\myenv\Lib\site-packages\django\core\handlers\exception.py", line 55, in inner
    response = get_response(request)
               ^^^^^^^^^^^^^^^^^^^^^
  File "C:\Users\HP\video-streaming-project\stream\myenv\Lib\site-packages\django\core\handlers\base.py", line 197, in _get_response
    response = wrapped_callback(request, *callback_args, **callback_kwargs)
               ^^^^^^^^^^^^^^^^^^^^^^^^^^^^^^^^^^^^^^^^^^^^^^^^^^^^^^^^^^^^
  File "C:\Users\HP\video-streaming-project\stream\myenv\Lib\site-packages\django\views\generic\base.py", line 104, in view
    return self.dispatch(request, *args, **kwargs)
           ^^^^^^^^^^^^^^^^^^^^^^^^^^^^^^^^^^^^^^^
  File "C:\Users\HP\video-streaming-project\stream\myenv\Lib\site-packages\django\views\generic\base.py", line 143, in dispatch
    return handler(request, *args, **kwargs)
           ^^^^^^^^^^^^^^^^^^^^^^^^^^^^^^^^^
  File "C:\Users\HP\ManishERP\ecommerce-ui\base\master\views\views_contact_master.py", line 39, in post
    return JsonResponse(response.json(), status=500)
                        ^^^^^^^^^^^^^^^
  File "C:\Users\HP\video-streaming-project\stream\myenv\Lib\site-packages\requests\models.py", line 978, in json
    raise RequestsJSONDecodeError(e.msg, e.doc, e.pos)
requests.exceptions.JSONDecodeError: Expecting value: line 1 column 1 (char 0)
2025-05-01 21:39:05,016 [ERROR] django.request: Internal Server Error: /master/generalSettings/create
Traceback (most recent call last):
  File "C:\Users\HP\video-streaming-project\stream\myenv\Lib\site-packages\requests\models.py", line 974, in json
    return complexjson.loads(self.text, **kwargs)
           ^^^^^^^^^^^^^^^^^^^^^^^^^^^^^^^^^^^^^^
  File "C:\Program Files\WindowsApps\PythonSoftwareFoundation.Python.3.12_3.12.2800.0_x64__qbz5n2kfra8p0\Lib\json\__init__.py", line 346, in loads
    return _default_decoder.decode(s)
           ^^^^^^^^^^^^^^^^^^^^^^^^^^
  File "C:\Program Files\WindowsApps\PythonSoftwareFoundation.Python.3.12_3.12.2800.0_x64__qbz5n2kfra8p0\Lib\json\decoder.py", line 338, in decode
    obj, end = self.raw_decode(s, idx=_w(s, 0).end())
               ^^^^^^^^^^^^^^^^^^^^^^^^^^^^^^^^^^^^^^
  File "C:\Program Files\WindowsApps\PythonSoftwareFoundation.Python.3.12_3.12.2800.0_x64__qbz5n2kfra8p0\Lib\json\decoder.py", line 356, in raw_decode
    raise JSONDecodeError("Expecting value", s, err.value) from None
json.decoder.JSONDecodeError: Expecting value: line 1 column 1 (char 0)

During handling of the above exception, another exception occurred:

Traceback (most recent call last):
  File "C:\Users\HP\video-streaming-project\stream\myenv\Lib\site-packages\django\core\handlers\exception.py", line 55, in inner
    response = get_response(request)
               ^^^^^^^^^^^^^^^^^^^^^
  File "C:\Users\HP\video-streaming-project\stream\myenv\Lib\site-packages\django\core\handlers\base.py", line 197, in _get_response
    response = wrapped_callback(request, *callback_args, **callback_kwargs)
               ^^^^^^^^^^^^^^^^^^^^^^^^^^^^^^^^^^^^^^^^^^^^^^^^^^^^^^^^^^^^
  File "C:\Users\HP\video-streaming-project\stream\myenv\Lib\site-packages\django\views\generic\base.py", line 104, in view
    return self.dispatch(request, *args, **kwargs)
           ^^^^^^^^^^^^^^^^^^^^^^^^^^^^^^^^^^^^^^^
  File "C:\Users\HP\video-streaming-project\stream\myenv\Lib\site-packages\django\views\generic\base.py", line 143, in dispatch
    return handler(request, *args, **kwargs)
           ^^^^^^^^^^^^^^^^^^^^^^^^^^^^^^^^^
  File "C:\Users\HP\ManishERP\ecommerce-ui\base\master\views\views_contact_master.py", line 39, in post
    return JsonResponse(response.json(), status=500)
                        ^^^^^^^^^^^^^^^
  File "C:\Users\HP\video-streaming-project\stream\myenv\Lib\site-packages\requests\models.py", line 978, in json
    raise RequestsJSONDecodeError(e.msg, e.doc, e.pos)
requests.exceptions.JSONDecodeError: Expecting value: line 1 column 1 (char 0)
2025-05-01 21:39:39,881 [ERROR] django.request: Internal Server Error: /master/generalSettings/create
Traceback (most recent call last):
  File "C:\Users\HP\video-streaming-project\stream\myenv\Lib\site-packages\requests\models.py", line 974, in json
    return complexjson.loads(self.text, **kwargs)
           ^^^^^^^^^^^^^^^^^^^^^^^^^^^^^^^^^^^^^^
  File "C:\Program Files\WindowsApps\PythonSoftwareFoundation.Python.3.12_3.12.2800.0_x64__qbz5n2kfra8p0\Lib\json\__init__.py", line 346, in loads
    return _default_decoder.decode(s)
           ^^^^^^^^^^^^^^^^^^^^^^^^^^
  File "C:\Program Files\WindowsApps\PythonSoftwareFoundation.Python.3.12_3.12.2800.0_x64__qbz5n2kfra8p0\Lib\json\decoder.py", line 338, in decode
    obj, end = self.raw_decode(s, idx=_w(s, 0).end())
               ^^^^^^^^^^^^^^^^^^^^^^^^^^^^^^^^^^^^^^
  File "C:\Program Files\WindowsApps\PythonSoftwareFoundation.Python.3.12_3.12.2800.0_x64__qbz5n2kfra8p0\Lib\json\decoder.py", line 356, in raw_decode
    raise JSONDecodeError("Expecting value", s, err.value) from None
json.decoder.JSONDecodeError: Expecting value: line 1 column 1 (char 0)

During handling of the above exception, another exception occurred:

Traceback (most recent call last):
  File "C:\Users\HP\video-streaming-project\stream\myenv\Lib\site-packages\django\core\handlers\exception.py", line 55, in inner
    response = get_response(request)
               ^^^^^^^^^^^^^^^^^^^^^
  File "C:\Users\HP\video-streaming-project\stream\myenv\Lib\site-packages\django\core\handlers\base.py", line 197, in _get_response
    response = wrapped_callback(request, *callback_args, **callback_kwargs)
               ^^^^^^^^^^^^^^^^^^^^^^^^^^^^^^^^^^^^^^^^^^^^^^^^^^^^^^^^^^^^
  File "C:\Users\HP\video-streaming-project\stream\myenv\Lib\site-packages\django\views\generic\base.py", line 104, in view
    return self.dispatch(request, *args, **kwargs)
           ^^^^^^^^^^^^^^^^^^^^^^^^^^^^^^^^^^^^^^^
  File "C:\Users\HP\video-streaming-project\stream\myenv\Lib\site-packages\django\views\generic\base.py", line 143, in dispatch
    return handler(request, *args, **kwargs)
           ^^^^^^^^^^^^^^^^^^^^^^^^^^^^^^^^^
  File "C:\Users\HP\ManishERP\ecommerce-ui\base\master\views\views_contact_master.py", line 39, in post
    return JsonResponse(response.json(), status=500)
                        ^^^^^^^^^^^^^^^
  File "C:\Users\HP\video-streaming-project\stream\myenv\Lib\site-packages\requests\models.py", line 978, in json
    raise RequestsJSONDecodeError(e.msg, e.doc, e.pos)
requests.exceptions.JSONDecodeError: Expecting value: line 1 column 1 (char 0)
2025-05-01 21:40:40,447 [ERROR] django.request: Internal Server Error: /master/generalSettings/create
Traceback (most recent call last):
  File "C:\Users\HP\video-streaming-project\stream\myenv\Lib\site-packages\requests\models.py", line 974, in json
    return complexjson.loads(self.text, **kwargs)
           ^^^^^^^^^^^^^^^^^^^^^^^^^^^^^^^^^^^^^^
  File "C:\Program Files\WindowsApps\PythonSoftwareFoundation.Python.3.12_3.12.2800.0_x64__qbz5n2kfra8p0\Lib\json\__init__.py", line 346, in loads
    return _default_decoder.decode(s)
           ^^^^^^^^^^^^^^^^^^^^^^^^^^
  File "C:\Program Files\WindowsApps\PythonSoftwareFoundation.Python.3.12_3.12.2800.0_x64__qbz5n2kfra8p0\Lib\json\decoder.py", line 338, in decode
    obj, end = self.raw_decode(s, idx=_w(s, 0).end())
               ^^^^^^^^^^^^^^^^^^^^^^^^^^^^^^^^^^^^^^
  File "C:\Program Files\WindowsApps\PythonSoftwareFoundation.Python.3.12_3.12.2800.0_x64__qbz5n2kfra8p0\Lib\json\decoder.py", line 356, in raw_decode
    raise JSONDecodeError("Expecting value", s, err.value) from None
json.decoder.JSONDecodeError: Expecting value: line 1 column 1 (char 0)

During handling of the above exception, another exception occurred:

Traceback (most recent call last):
  File "C:\Users\HP\video-streaming-project\stream\myenv\Lib\site-packages\django\core\handlers\exception.py", line 55, in inner
    response = get_response(request)
               ^^^^^^^^^^^^^^^^^^^^^
  File "C:\Users\HP\video-streaming-project\stream\myenv\Lib\site-packages\django\core\handlers\base.py", line 197, in _get_response
    response = wrapped_callback(request, *callback_args, **callback_kwargs)
               ^^^^^^^^^^^^^^^^^^^^^^^^^^^^^^^^^^^^^^^^^^^^^^^^^^^^^^^^^^^^
  File "C:\Users\HP\video-streaming-project\stream\myenv\Lib\site-packages\django\views\generic\base.py", line 104, in view
    return self.dispatch(request, *args, **kwargs)
           ^^^^^^^^^^^^^^^^^^^^^^^^^^^^^^^^^^^^^^^
  File "C:\Users\HP\video-streaming-project\stream\myenv\Lib\site-packages\django\views\generic\base.py", line 143, in dispatch
    return handler(request, *args, **kwargs)
           ^^^^^^^^^^^^^^^^^^^^^^^^^^^^^^^^^
  File "C:\Users\HP\ManishERP\ecommerce-ui\base\master\views\views_contact_master.py", line 39, in post
    return JsonResponse(response.json(), status=500)
                        ^^^^^^^^^^^^^^^
  File "C:\Users\HP\video-streaming-project\stream\myenv\Lib\site-packages\requests\models.py", line 978, in json
    raise RequestsJSONDecodeError(e.msg, e.doc, e.pos)
requests.exceptions.JSONDecodeError: Expecting value: line 1 column 1 (char 0)
2025-05-01 21:40:54,294 [ERROR] django.request: Internal Server Error: /master/generalSettings/create
Traceback (most recent call last):
  File "C:\Users\HP\video-streaming-project\stream\myenv\Lib\site-packages\requests\models.py", line 974, in json
    return complexjson.loads(self.text, **kwargs)
           ^^^^^^^^^^^^^^^^^^^^^^^^^^^^^^^^^^^^^^
  File "C:\Program Files\WindowsApps\PythonSoftwareFoundation.Python.3.12_3.12.2800.0_x64__qbz5n2kfra8p0\Lib\json\__init__.py", line 346, in loads
    return _default_decoder.decode(s)
           ^^^^^^^^^^^^^^^^^^^^^^^^^^
  File "C:\Program Files\WindowsApps\PythonSoftwareFoundation.Python.3.12_3.12.2800.0_x64__qbz5n2kfra8p0\Lib\json\decoder.py", line 338, in decode
    obj, end = self.raw_decode(s, idx=_w(s, 0).end())
               ^^^^^^^^^^^^^^^^^^^^^^^^^^^^^^^^^^^^^^
  File "C:\Program Files\WindowsApps\PythonSoftwareFoundation.Python.3.12_3.12.2800.0_x64__qbz5n2kfra8p0\Lib\json\decoder.py", line 356, in raw_decode
    raise JSONDecodeError("Expecting value", s, err.value) from None
json.decoder.JSONDecodeError: Expecting value: line 1 column 1 (char 0)

During handling of the above exception, another exception occurred:

Traceback (most recent call last):
  File "C:\Users\HP\video-streaming-project\stream\myenv\Lib\site-packages\django\core\handlers\exception.py", line 55, in inner
    response = get_response(request)
               ^^^^^^^^^^^^^^^^^^^^^
  File "C:\Users\HP\video-streaming-project\stream\myenv\Lib\site-packages\django\core\handlers\base.py", line 197, in _get_response
    response = wrapped_callback(request, *callback_args, **callback_kwargs)
               ^^^^^^^^^^^^^^^^^^^^^^^^^^^^^^^^^^^^^^^^^^^^^^^^^^^^^^^^^^^^
  File "C:\Users\HP\video-streaming-project\stream\myenv\Lib\site-packages\django\views\generic\base.py", line 104, in view
    return self.dispatch(request, *args, **kwargs)
           ^^^^^^^^^^^^^^^^^^^^^^^^^^^^^^^^^^^^^^^
  File "C:\Users\HP\video-streaming-project\stream\myenv\Lib\site-packages\django\views\generic\base.py", line 143, in dispatch
    return handler(request, *args, **kwargs)
           ^^^^^^^^^^^^^^^^^^^^^^^^^^^^^^^^^
  File "C:\Users\HP\ManishERP\ecommerce-ui\base\master\views\views_contact_master.py", line 39, in post
    return JsonResponse(response.json(), status=500)
                        ^^^^^^^^^^^^^^^
  File "C:\Users\HP\video-streaming-project\stream\myenv\Lib\site-packages\requests\models.py", line 978, in json
    raise RequestsJSONDecodeError(e.msg, e.doc, e.pos)
requests.exceptions.JSONDecodeError: Expecting value: line 1 column 1 (char 0)
2025-05-01 21:41:37,811 [ERROR] django.request: Internal Server Error: /master/generalSettings/create
Traceback (most recent call last):
  File "C:\Users\HP\video-streaming-project\stream\myenv\Lib\site-packages\requests\models.py", line 974, in json
    return complexjson.loads(self.text, **kwargs)
           ^^^^^^^^^^^^^^^^^^^^^^^^^^^^^^^^^^^^^^
  File "C:\Program Files\WindowsApps\PythonSoftwareFoundation.Python.3.12_3.12.2800.0_x64__qbz5n2kfra8p0\Lib\json\__init__.py", line 346, in loads
    return _default_decoder.decode(s)
           ^^^^^^^^^^^^^^^^^^^^^^^^^^
  File "C:\Program Files\WindowsApps\PythonSoftwareFoundation.Python.3.12_3.12.2800.0_x64__qbz5n2kfra8p0\Lib\json\decoder.py", line 338, in decode
    obj, end = self.raw_decode(s, idx=_w(s, 0).end())
               ^^^^^^^^^^^^^^^^^^^^^^^^^^^^^^^^^^^^^^
  File "C:\Program Files\WindowsApps\PythonSoftwareFoundation.Python.3.12_3.12.2800.0_x64__qbz5n2kfra8p0\Lib\json\decoder.py", line 356, in raw_decode
    raise JSONDecodeError("Expecting value", s, err.value) from None
json.decoder.JSONDecodeError: Expecting value: line 1 column 1 (char 0)

During handling of the above exception, another exception occurred:

Traceback (most recent call last):
  File "C:\Users\HP\video-streaming-project\stream\myenv\Lib\site-packages\django\core\handlers\exception.py", line 55, in inner
    response = get_response(request)
               ^^^^^^^^^^^^^^^^^^^^^
  File "C:\Users\HP\video-streaming-project\stream\myenv\Lib\site-packages\django\core\handlers\base.py", line 197, in _get_response
    response = wrapped_callback(request, *callback_args, **callback_kwargs)
               ^^^^^^^^^^^^^^^^^^^^^^^^^^^^^^^^^^^^^^^^^^^^^^^^^^^^^^^^^^^^
  File "C:\Users\HP\video-streaming-project\stream\myenv\Lib\site-packages\django\views\generic\base.py", line 104, in view
    return self.dispatch(request, *args, **kwargs)
           ^^^^^^^^^^^^^^^^^^^^^^^^^^^^^^^^^^^^^^^
  File "C:\Users\HP\video-streaming-project\stream\myenv\Lib\site-packages\django\views\generic\base.py", line 143, in dispatch
    return handler(request, *args, **kwargs)
           ^^^^^^^^^^^^^^^^^^^^^^^^^^^^^^^^^
  File "C:\Users\HP\ManishERP\ecommerce-ui\base\master\views\views_contact_master.py", line 39, in post
    return JsonResponse(response.json(), status=500)
                        ^^^^^^^^^^^^^^^
  File "C:\Users\HP\video-streaming-project\stream\myenv\Lib\site-packages\requests\models.py", line 978, in json
    raise RequestsJSONDecodeError(e.msg, e.doc, e.pos)
requests.exceptions.JSONDecodeError: Expecting value: line 1 column 1 (char 0)
2025-05-01 21:41:37,844 [ERROR] django.request: Internal Server Error: /master/generalSettings/create
Traceback (most recent call last):
  File "C:\Users\HP\video-streaming-project\stream\myenv\Lib\site-packages\requests\models.py", line 974, in json
    return complexjson.loads(self.text, **kwargs)
           ^^^^^^^^^^^^^^^^^^^^^^^^^^^^^^^^^^^^^^
  File "C:\Program Files\WindowsApps\PythonSoftwareFoundation.Python.3.12_3.12.2800.0_x64__qbz5n2kfra8p0\Lib\json\__init__.py", line 346, in loads
    return _default_decoder.decode(s)
           ^^^^^^^^^^^^^^^^^^^^^^^^^^
  File "C:\Program Files\WindowsApps\PythonSoftwareFoundation.Python.3.12_3.12.2800.0_x64__qbz5n2kfra8p0\Lib\json\decoder.py", line 338, in decode
    obj, end = self.raw_decode(s, idx=_w(s, 0).end())
               ^^^^^^^^^^^^^^^^^^^^^^^^^^^^^^^^^^^^^^
  File "C:\Program Files\WindowsApps\PythonSoftwareFoundation.Python.3.12_3.12.2800.0_x64__qbz5n2kfra8p0\Lib\json\decoder.py", line 356, in raw_decode
    raise JSONDecodeError("Expecting value", s, err.value) from None
json.decoder.JSONDecodeError: Expecting value: line 1 column 1 (char 0)

During handling of the above exception, another exception occurred:

Traceback (most recent call last):
  File "C:\Users\HP\video-streaming-project\stream\myenv\Lib\site-packages\django\core\handlers\exception.py", line 55, in inner
    response = get_response(request)
               ^^^^^^^^^^^^^^^^^^^^^
  File "C:\Users\HP\video-streaming-project\stream\myenv\Lib\site-packages\django\core\handlers\base.py", line 197, in _get_response
    response = wrapped_callback(request, *callback_args, **callback_kwargs)
               ^^^^^^^^^^^^^^^^^^^^^^^^^^^^^^^^^^^^^^^^^^^^^^^^^^^^^^^^^^^^
  File "C:\Users\HP\video-streaming-project\stream\myenv\Lib\site-packages\django\views\generic\base.py", line 104, in view
    return self.dispatch(request, *args, **kwargs)
           ^^^^^^^^^^^^^^^^^^^^^^^^^^^^^^^^^^^^^^^
  File "C:\Users\HP\video-streaming-project\stream\myenv\Lib\site-packages\django\views\generic\base.py", line 143, in dispatch
    return handler(request, *args, **kwargs)
           ^^^^^^^^^^^^^^^^^^^^^^^^^^^^^^^^^
  File "C:\Users\HP\ManishERP\ecommerce-ui\base\master\views\views_contact_master.py", line 39, in post
    return JsonResponse(response.json(), status=500)
                        ^^^^^^^^^^^^^^^
  File "C:\Users\HP\video-streaming-project\stream\myenv\Lib\site-packages\requests\models.py", line 978, in json
    raise RequestsJSONDecodeError(e.msg, e.doc, e.pos)
requests.exceptions.JSONDecodeError: Expecting value: line 1 column 1 (char 0)
2025-05-01 21:42:08,708 [ERROR] django.request: Internal Server Error: /master/generalSettings/create
2025-05-01 21:43:39,520 [ERROR] django.request: Internal Server Error: /master/generalSettings/create
2025-05-01 21:44:05,274 [WARNING] django.request: Not Found: /user/logout/
2025-05-01 21:44:06,040 [WARNING] django.request: Not Found: /favicon.ico
2025-05-01 21:49:10,011 [WARNING] django.request: Not Found: /user/logout/
2025-05-01 21:49:10,558 [WARNING] django.request: Not Found: /favicon.ico
2025-05-01 21:49:47,225 [WARNING] django.request: Not Found: /user/logout/
2025-05-01 21:49:47,850 [WARNING] django.request: Not Found: /favicon.ico
2025-05-01 21:49:47,956 [ERROR] django.request: Internal Server Error: /master/generalSettings/list
Traceback (most recent call last):
  File "C:\Users\HP\video-streaming-project\stream\myenv\Lib\site-packages\requests\models.py", line 974, in json
    return complexjson.loads(self.text, **kwargs)
           ^^^^^^^^^^^^^^^^^^^^^^^^^^^^^^^^^^^^^^
  File "C:\Program Files\WindowsApps\PythonSoftwareFoundation.Python.3.12_3.12.2800.0_x64__qbz5n2kfra8p0\Lib\json\__init__.py", line 346, in loads
    return _default_decoder.decode(s)
           ^^^^^^^^^^^^^^^^^^^^^^^^^^
  File "C:\Program Files\WindowsApps\PythonSoftwareFoundation.Python.3.12_3.12.2800.0_x64__qbz5n2kfra8p0\Lib\json\decoder.py", line 338, in decode
    obj, end = self.raw_decode(s, idx=_w(s, 0).end())
               ^^^^^^^^^^^^^^^^^^^^^^^^^^^^^^^^^^^^^^
  File "C:\Program Files\WindowsApps\PythonSoftwareFoundation.Python.3.12_3.12.2800.0_x64__qbz5n2kfra8p0\Lib\json\decoder.py", line 356, in raw_decode
    raise JSONDecodeError("Expecting value", s, err.value) from None
json.decoder.JSONDecodeError: Expecting value: line 1 column 1 (char 0)

During handling of the above exception, another exception occurred:

Traceback (most recent call last):
  File "C:\Users\HP\video-streaming-project\stream\myenv\Lib\site-packages\django\core\handlers\exception.py", line 55, in inner
    response = get_response(request)
               ^^^^^^^^^^^^^^^^^^^^^
  File "C:\Users\HP\video-streaming-project\stream\myenv\Lib\site-packages\django\core\handlers\base.py", line 197, in _get_response
    response = wrapped_callback(request, *callback_args, **callback_kwargs)
               ^^^^^^^^^^^^^^^^^^^^^^^^^^^^^^^^^^^^^^^^^^^^^^^^^^^^^^^^^^^^
  File "C:\Users\HP\video-streaming-project\stream\myenv\Lib\site-packages\django\views\generic\base.py", line 104, in view
    return self.dispatch(request, *args, **kwargs)
           ^^^^^^^^^^^^^^^^^^^^^^^^^^^^^^^^^^^^^^^
  File "C:\Users\HP\video-streaming-project\stream\myenv\Lib\site-packages\django\views\generic\base.py", line 143, in dispatch
    return handler(request, *args, **kwargs)
           ^^^^^^^^^^^^^^^^^^^^^^^^^^^^^^^^^
  File "C:\Users\HP\ManishERP\ecommerce-ui\base\master\views\views_contact_master.py", line 59, in get
    return JsonResponse(response.json(), status=500)
                        ^^^^^^^^^^^^^^^
  File "C:\Users\HP\video-streaming-project\stream\myenv\Lib\site-packages\requests\models.py", line 978, in json
    raise RequestsJSONDecodeError(e.msg, e.doc, e.pos)
requests.exceptions.JSONDecodeError: Expecting value: line 1 column 1 (char 0)
2025-05-01 21:50:34,630 [WARNING] django.request: Not Found: /user/logout/
2025-05-01 21:50:35,001 [WARNING] django.request: Not Found: /favicon.ico
2025-05-01 21:50:35,035 [WARNING] django.request: Not Found: /user/logout/
2025-05-01 21:50:35,149 [WARNING] django.request: Not Found: /user/logout/
2025-05-01 21:50:35,253 [WARNING] django.request: Not Found: /user/logout/
2025-05-01 21:50:35,351 [WARNING] django.request: Not Found: /user/logout/
2025-05-01 21:50:35,365 [WARNING] django.request: Not Found: /user/logout/
2025-05-01 21:50:35,391 [WARNING] django.request: Not Found: /user/logout/
2025-05-01 21:50:35,713 [WARNING] django.request: Not Found: /favicon.ico
2025-05-01 21:52:24,076 [WARNING] django.request: Not Found: /user/logout/
2025-05-01 21:52:24,818 [WARNING] django.request: Not Found: /favicon.ico
2025-05-01 21:53:18,139 [WARNING] django.request: Not Found: /user/logout/
2025-05-01 21:53:18,590 [WARNING] django.request: Not Found: /user/logout/
2025-05-01 21:53:19,197 [WARNING] django.request: Not Found: /favicon.ico
2025-05-01 22:06:00,208 [WARNING] django.request: Not Found: /user/logout/
2025-05-02 22:30:51,934 [WARNING] django.request: Not Found: /favicon.ico
2025-05-02 22:38:26,562 [WARNING] django.request: Not Found: /dashboard/dist/img/default-150x150.png
2025-05-02 22:38:26,636 [WARNING] django.request: Not Found: /dashboard/dist/img/default-150x150.png
2025-05-02 22:38:26,983 [ERROR] django.request: Internal Server Error: /products/productsList
Traceback (most recent call last):
  File "C:\Users\HP\video-streaming-project\stream\myenv\Lib\site-packages\requests\models.py", line 974, in json
    return complexjson.loads(self.text, **kwargs)
           ^^^^^^^^^^^^^^^^^^^^^^^^^^^^^^^^^^^^^^
  File "C:\Program Files\WindowsApps\PythonSoftwareFoundation.Python.3.12_3.12.2800.0_x64__qbz5n2kfra8p0\Lib\json\__init__.py", line 346, in loads
    return _default_decoder.decode(s)
           ^^^^^^^^^^^^^^^^^^^^^^^^^^
  File "C:\Program Files\WindowsApps\PythonSoftwareFoundation.Python.3.12_3.12.2800.0_x64__qbz5n2kfra8p0\Lib\json\decoder.py", line 338, in decode
    obj, end = self.raw_decode(s, idx=_w(s, 0).end())
               ^^^^^^^^^^^^^^^^^^^^^^^^^^^^^^^^^^^^^^
  File "C:\Program Files\WindowsApps\PythonSoftwareFoundation.Python.3.12_3.12.2800.0_x64__qbz5n2kfra8p0\Lib\json\decoder.py", line 356, in raw_decode
    raise JSONDecodeError("Expecting value", s, err.value) from None
json.decoder.JSONDecodeError: Expecting value: line 1 column 1 (char 0)

During handling of the above exception, another exception occurred:

Traceback (most recent call last):
  File "C:\Users\HP\video-streaming-project\stream\myenv\Lib\site-packages\django\core\handlers\exception.py", line 55, in inner
    response = get_response(request)
               ^^^^^^^^^^^^^^^^^^^^^
  File "C:\Users\HP\video-streaming-project\stream\myenv\Lib\site-packages\django\core\handlers\base.py", line 197, in _get_response
    response = wrapped_callback(request, *callback_args, **callback_kwargs)
               ^^^^^^^^^^^^^^^^^^^^^^^^^^^^^^^^^^^^^^^^^^^^^^^^^^^^^^^^^^^^
  File "C:\Users\HP\video-streaming-project\stream\myenv\Lib\site-packages\django\views\generic\base.py", line 104, in view
    return self.dispatch(request, *args, **kwargs)
           ^^^^^^^^^^^^^^^^^^^^^^^^^^^^^^^^^^^^^^^
  File "C:\Users\HP\video-streaming-project\stream\myenv\Lib\site-packages\django\views\generic\base.py", line 143, in dispatch
    return handler(request, *args, **kwargs)
           ^^^^^^^^^^^^^^^^^^^^^^^^^^^^^^^^^
  File "C:\Users\HP\ManishERP\ecommerce-ui\base\products\views.py", line 25, in get
    data = response.json()
           ^^^^^^^^^^^^^^^
  File "C:\Users\HP\video-streaming-project\stream\myenv\Lib\site-packages\requests\models.py", line 978, in json
    raise RequestsJSONDecodeError(e.msg, e.doc, e.pos)
requests.exceptions.JSONDecodeError: Expecting value: line 1 column 1 (char 0)
2025-05-02 22:38:30,613 [WARNING] django.request: Not Found: /user/logout/
2025-05-02 22:53:32,756 [ERROR] django.request: Internal Server Error: /master/generalSettings/create
2025-05-02 23:00:02,921 [ERROR] django.request: Internal Server Error: /master/generalSettings/create
Traceback (most recent call last):
  File "C:\Users\HP\video-streaming-project\stream\myenv\Lib\site-packages\requests\models.py", line 974, in json
    return complexjson.loads(self.text, **kwargs)
           ^^^^^^^^^^^^^^^^^^^^^^^^^^^^^^^^^^^^^^
  File "C:\Program Files\WindowsApps\PythonSoftwareFoundation.Python.3.12_3.12.2800.0_x64__qbz5n2kfra8p0\Lib\json\__init__.py", line 346, in loads
    return _default_decoder.decode(s)
           ^^^^^^^^^^^^^^^^^^^^^^^^^^
  File "C:\Program Files\WindowsApps\PythonSoftwareFoundation.Python.3.12_3.12.2800.0_x64__qbz5n2kfra8p0\Lib\json\decoder.py", line 338, in decode
    obj, end = self.raw_decode(s, idx=_w(s, 0).end())
               ^^^^^^^^^^^^^^^^^^^^^^^^^^^^^^^^^^^^^^
  File "C:\Program Files\WindowsApps\PythonSoftwareFoundation.Python.3.12_3.12.2800.0_x64__qbz5n2kfra8p0\Lib\json\decoder.py", line 356, in raw_decode
    raise JSONDecodeError("Expecting value", s, err.value) from None
json.decoder.JSONDecodeError: Expecting value: line 1 column 1 (char 0)

During handling of the above exception, another exception occurred:

Traceback (most recent call last):
  File "C:\Users\HP\video-streaming-project\stream\myenv\Lib\site-packages\django\core\handlers\exception.py", line 55, in inner
    response = get_response(request)
               ^^^^^^^^^^^^^^^^^^^^^
  File "C:\Users\HP\video-streaming-project\stream\myenv\Lib\site-packages\django\core\handlers\base.py", line 197, in _get_response
    response = wrapped_callback(request, *callback_args, **callback_kwargs)
               ^^^^^^^^^^^^^^^^^^^^^^^^^^^^^^^^^^^^^^^^^^^^^^^^^^^^^^^^^^^^
  File "C:\Users\HP\video-streaming-project\stream\myenv\Lib\site-packages\django\views\generic\base.py", line 104, in view
    return self.dispatch(request, *args, **kwargs)
           ^^^^^^^^^^^^^^^^^^^^^^^^^^^^^^^^^^^^^^^
  File "C:\Users\HP\video-streaming-project\stream\myenv\Lib\site-packages\django\views\generic\base.py", line 143, in dispatch
    return handler(request, *args, **kwargs)
           ^^^^^^^^^^^^^^^^^^^^^^^^^^^^^^^^^
  File "C:\Users\HP\ManishERP\ecommerce-ui\base\master\views\views_contact_master.py", line 39, in post
    return JsonResponse(response.json(), status=500)
                        ^^^^^^^^^^^^^^^
  File "C:\Users\HP\video-streaming-project\stream\myenv\Lib\site-packages\requests\models.py", line 978, in json
    raise RequestsJSONDecodeError(e.msg, e.doc, e.pos)
requests.exceptions.JSONDecodeError: Expecting value: line 1 column 1 (char 0)
2025-05-02 23:01:47,949 [ERROR] django.request: Internal Server Error: /master/generalSettings/create
Traceback (most recent call last):
  File "C:\Users\HP\video-streaming-project\stream\myenv\Lib\site-packages\requests\models.py", line 974, in json
    return complexjson.loads(self.text, **kwargs)
           ^^^^^^^^^^^^^^^^^^^^^^^^^^^^^^^^^^^^^^
  File "C:\Program Files\WindowsApps\PythonSoftwareFoundation.Python.3.12_3.12.2800.0_x64__qbz5n2kfra8p0\Lib\json\__init__.py", line 346, in loads
    return _default_decoder.decode(s)
           ^^^^^^^^^^^^^^^^^^^^^^^^^^
  File "C:\Program Files\WindowsApps\PythonSoftwareFoundation.Python.3.12_3.12.2800.0_x64__qbz5n2kfra8p0\Lib\json\decoder.py", line 338, in decode
    obj, end = self.raw_decode(s, idx=_w(s, 0).end())
               ^^^^^^^^^^^^^^^^^^^^^^^^^^^^^^^^^^^^^^
  File "C:\Program Files\WindowsApps\PythonSoftwareFoundation.Python.3.12_3.12.2800.0_x64__qbz5n2kfra8p0\Lib\json\decoder.py", line 356, in raw_decode
    raise JSONDecodeError("Expecting value", s, err.value) from None
json.decoder.JSONDecodeError: Expecting value: line 1 column 1 (char 0)

During handling of the above exception, another exception occurred:

Traceback (most recent call last):
  File "C:\Users\HP\video-streaming-project\stream\myenv\Lib\site-packages\django\core\handlers\exception.py", line 55, in inner
    response = get_response(request)
               ^^^^^^^^^^^^^^^^^^^^^
  File "C:\Users\HP\video-streaming-project\stream\myenv\Lib\site-packages\django\core\handlers\base.py", line 197, in _get_response
    response = wrapped_callback(request, *callback_args, **callback_kwargs)
               ^^^^^^^^^^^^^^^^^^^^^^^^^^^^^^^^^^^^^^^^^^^^^^^^^^^^^^^^^^^^
  File "C:\Users\HP\video-streaming-project\stream\myenv\Lib\site-packages\django\views\generic\base.py", line 104, in view
    return self.dispatch(request, *args, **kwargs)
           ^^^^^^^^^^^^^^^^^^^^^^^^^^^^^^^^^^^^^^^
  File "C:\Users\HP\video-streaming-project\stream\myenv\Lib\site-packages\django\views\generic\base.py", line 143, in dispatch
    return handler(request, *args, **kwargs)
           ^^^^^^^^^^^^^^^^^^^^^^^^^^^^^^^^^
  File "C:\Users\HP\ManishERP\ecommerce-ui\base\master\views\views_contact_master.py", line 39, in post
    return JsonResponse(response.json(), status=500)
                        ^^^^^^^^^^^^^^^
  File "C:\Users\HP\video-streaming-project\stream\myenv\Lib\site-packages\requests\models.py", line 978, in json
    raise RequestsJSONDecodeError(e.msg, e.doc, e.pos)
requests.exceptions.JSONDecodeError: Expecting value: line 1 column 1 (char 0)
2025-05-02 23:02:14,956 [ERROR] django.request: Internal Server Error: /master/generalSettings/create
2025-05-02 23:03:39,495 [ERROR] django.request: Internal Server Error: /master/generalSettings/create
2025-05-02 23:05:08,861 [WARNING] django.request: Not Found: /user/logout/
2025-05-02 23:05:12,308 [ERROR] django.request: Internal Server Error: /orders/ordersList
2025-05-02 23:05:22,231 [WARNING] django.request: Not Found: /user/logout/
2025-05-02 23:05:31,825 [WARNING] django.request: Not Found: /user/logout/
2025-05-02 23:28:36,632 [WARNING] django.request: Not Found: /user/logout/
2025-05-02 23:28:37,429 [WARNING] django.request: Not Found: /favicon.ico
2025-05-02 23:29:37,929 [WARNING] django.request: Not Found: /user/logout/
2025-05-02 23:29:38,921 [WARNING] django.request: Not Found: /favicon.ico
2025-05-02 23:29:44,201 [WARNING] django.request: Not Found: /user/logout/
2025-05-02 23:29:44,387 [ERROR] django.request: Internal Server Error: /loanApplication/lead/create
Traceback (most recent call last):
  File "C:\Users\HP\video-streaming-project\stream\myenv\Lib\site-packages\django\core\handlers\exception.py", line 55, in inner
    response = get_response(request)
               ^^^^^^^^^^^^^^^^^^^^^
  File "C:\Users\HP\video-streaming-project\stream\myenv\Lib\site-packages\django\core\handlers\base.py", line 197, in _get_response
    response = wrapped_callback(request, *callback_args, **callback_kwargs)
               ^^^^^^^^^^^^^^^^^^^^^^^^^^^^^^^^^^^^^^^^^^^^^^^^^^^^^^^^^^^^
  File "C:\Users\HP\video-streaming-project\stream\myenv\Lib\site-packages\django\views\generic\base.py", line 104, in view
    return self.dispatch(request, *args, **kwargs)
           ^^^^^^^^^^^^^^^^^^^^^^^^^^^^^^^^^^^^^^^
  File "C:\Users\HP\video-streaming-project\stream\myenv\Lib\site-packages\django\views\generic\base.py", line 143, in dispatch
    return handler(request, *args, **kwargs)
           ^^^^^^^^^^^^^^^^^^^^^^^^^^^^^^^^^
  File "C:\Users\HP\ManishERP\ecommerce-ui\base\loan_application\views\views_loan_application.py", line 7, in get
    return render(request,'loan_application/loan_application_create.html')
           ^^^^^^^^^^^^^^^^^^^^^^^^^^^^^^^^^^^^^^^^^^^^^^^^^^^^^^^^^^^^^^^
  File "C:\Users\HP\video-streaming-project\stream\myenv\Lib\site-packages\django\shortcuts.py", line 25, in render
    content = loader.render_to_string(template_name, context, request, using=using)
              ^^^^^^^^^^^^^^^^^^^^^^^^^^^^^^^^^^^^^^^^^^^^^^^^^^^^^^^^^^^^^^^^^^^^^
  File "C:\Users\HP\video-streaming-project\stream\myenv\Lib\site-packages\django\template\loader.py", line 61, in render_to_string
    template = get_template(template_name, using=using)
               ^^^^^^^^^^^^^^^^^^^^^^^^^^^^^^^^^^^^^^^^
  File "C:\Users\HP\video-streaming-project\stream\myenv\Lib\site-packages\django\template\loader.py", line 15, in get_template
    return engine.get_template(template_name)
           ^^^^^^^^^^^^^^^^^^^^^^^^^^^^^^^^^^
  File "C:\Users\HP\video-streaming-project\stream\myenv\Lib\site-packages\django\template\backends\django.py", line 79, in get_template
    return Template(self.engine.get_template(template_name), self)
                    ^^^^^^^^^^^^^^^^^^^^^^^^^^^^^^^^^^^^^^^
  File "C:\Users\HP\video-streaming-project\stream\myenv\Lib\site-packages\django\template\engine.py", line 177, in get_template
    template, origin = self.find_template(template_name)
                       ^^^^^^^^^^^^^^^^^^^^^^^^^^^^^^^^^
  File "C:\Users\HP\video-streaming-project\stream\myenv\Lib\site-packages\django\template\engine.py", line 159, in find_template
    template = loader.get_template(name, skip=skip)
               ^^^^^^^^^^^^^^^^^^^^^^^^^^^^^^^^^^^^
  File "C:\Users\HP\video-streaming-project\stream\myenv\Lib\site-packages\django\template\loaders\cached.py", line 57, in get_template
    template = super().get_template(template_name, skip)
               ^^^^^^^^^^^^^^^^^^^^^^^^^^^^^^^^^^^^^^^^^
  File "C:\Users\HP\video-streaming-project\stream\myenv\Lib\site-packages\django\template\loaders\base.py", line 28, in get_template
    return Template(
           ^^^^^^^^^
  File "C:\Users\HP\video-streaming-project\stream\myenv\Lib\site-packages\django\template\base.py", line 154, in __init__
    self.nodelist = self.compile_nodelist()
                    ^^^^^^^^^^^^^^^^^^^^^^^
  File "C:\Users\HP\video-streaming-project\stream\myenv\Lib\site-packages\django\template\base.py", line 196, in compile_nodelist
    nodelist = parser.parse()
               ^^^^^^^^^^^^^^
  File "C:\Users\HP\video-streaming-project\stream\myenv\Lib\site-packages\django\template\base.py", line 518, in parse
    raise self.error(token, e)
  File "C:\Users\HP\video-streaming-project\stream\myenv\Lib\site-packages\django\template\base.py", line 516, in parse
    compiled_result = compile_func(self, token)
                      ^^^^^^^^^^^^^^^^^^^^^^^^^
  File "C:\Users\HP\video-streaming-project\stream\myenv\Lib\site-packages\django\template\loader_tags.py", line 295, in do_extends
    nodelist = parser.parse()
               ^^^^^^^^^^^^^^
  File "C:\Users\HP\video-streaming-project\stream\myenv\Lib\site-packages\django\template\base.py", line 518, in parse
    raise self.error(token, e)
  File "C:\Users\HP\video-streaming-project\stream\myenv\Lib\site-packages\django\template\base.py", line 516, in parse
    compiled_result = compile_func(self, token)
                      ^^^^^^^^^^^^^^^^^^^^^^^^^
  File "C:\Users\HP\video-streaming-project\stream\myenv\Lib\site-packages\django\template\loader_tags.py", line 234, in do_block
    nodelist = parser.parse(("endblock",))
               ^^^^^^^^^^^^^^^^^^^^^^^^^^^
  File "C:\Users\HP\video-streaming-project\stream\myenv\Lib\site-packages\django\template\base.py", line 523, in parse
    self.unclosed_block_tag(parse_until)
  File "C:\Users\HP\video-streaming-project\stream\myenv\Lib\site-packages\django\template\base.py", line 586, in unclosed_block_tag
    raise self.error(token, msg)
django.template.exceptions.TemplateSyntaxError: Unclosed tag on line 5: 'block'. Looking for one of: endblock.
2025-05-02 23:30:33,317 [WARNING] django.request: Not Found: /favicon.ico
2025-05-02 23:31:33,080 [WARNING] django.request: Not Found: /user/logout/
2025-05-02 23:31:33,827 [WARNING] django.request: Not Found: /favicon.ico
2025-05-02 23:34:42,596 [WARNING] django.request: Not Found: /user/logout/
2025-05-02 23:34:43,495 [WARNING] django.request: Not Found: /favicon.ico
2025-05-02 23:36:06,201 [WARNING] django.request: Not Found: /user/logout/
2025-05-02 23:36:06,974 [WARNING] django.request: Not Found: /favicon.ico
2025-05-02 23:37:08,426 [WARNING] django.request: Not Found: /user/logout/
2025-05-02 23:37:09,161 [WARNING] django.request: Not Found: /favicon.ico
2025-05-02 23:40:55,067 [WARNING] django.request: Not Found: /user/logout/
2025-05-02 23:40:55,958 [WARNING] django.request: Not Found: /favicon.ico
2025-05-02 23:41:02,859 [WARNING] django.request: Not Found: /user/logout/
2025-05-02 23:41:05,440 [WARNING] django.request: Not Found: /user/logout/
2025-05-02 23:41:06,977 [WARNING] django.request: Not Found: /user/logout/
2025-05-02 23:41:07,476 [WARNING] django.request: Not Found: /favicon.ico
2025-05-02 23:41:22,780 [WARNING] django.request: Not Found: /user/logout/
